<?xml version="1.0"?>
<sdf version="1.6">
    <model name="model_1">
      <link name="link_1">
        <pose>0 0 2.0 0 0 0</pose>
        <inertial>
          <inertia>
            <ixx>0.100000</ixx>
            <ixy>0.000000</ixy>
            <ixz>0.000000</ixz>
            <iyy>0.100000</iyy>
            <iyz>0.000000</iyz>
            <izz>0.100000</izz>
          </inertia>
          <mass>5.000000</mass>
        </inertial>
        <visual name="visual_sphere">
          <geometry>
            <sphere>
              <radius>0.050000</radius>
            </sphere>
          </geometry>
        </visual>
        <visual name="visual_cylinder">
          <pose>0 0 -0.25 0 0 0</pose>
          <geometry>
            <cylinder>
              <radius>0.0100000</radius>
              <length>0.5</length>
            </cylinder>
          </geometry>
        </visual>
        <collision name="collision_sphere">
          <max_contacts>250</max_contacts>
          <geometry>
            <sphere>
              <radius>0.050000</radius>
            </sphere>
          </geometry>
        </collision>
      </link>
      <joint name="joint_01" type="ball">
        <parent>world</parent>
        <child>link_1</child>
        <pose>0 0 -0.5 0 0 0</pose>
        <axis>
          <dynamics>
            <damping>1.000000</damping>
            <friction>100.000000</friction>
            <spring_reference>1.000000</spring_reference>
            <spring_stiffness>1.000000</spring_stiffness>
          </dynamics>
          <xyz>1.000000 0.000000 0.000000</xyz>
        </axis>
        <sensor name="force_torque" type="force_torque">
          <update_rate>30</update_rate>
        </sensor>
      </joint>
    </model>
</sdf>